const asyncHandler = (requestHandler) => {
  (req, res, next) => {
    Promise.resolve(requestHandler(req, res, next)).catch((err) => next(err));
  };
};

export { asyncHandler };

// another way to handle this using try catch:
/*
const asyncHandlerTC = (fn) => async (req, res, next) => {
  try {
    await fn(req, res, next);
  } catch (error) {
    res.status(err.code || 500).json({
      success: false,
      message: err.message,
    });
  }
};
*/